[2025-08-17T21:38:26.518+0000] {local_task_job_runner.py:123} INFO - ::group::Pre task execution logs
[2025-08-17T21:38:26.551+0000] {taskinstance.py:2603} INFO - Dependencies all met for dep_context=non-requeueable deps ti=<TaskInstance: citybikes_monitoring.get_and_insert_task scheduled__2025-08-17T00:07:00+00:00 [queued]>
[2025-08-17T21:38:26.566+0000] {taskinstance.py:2603} INFO - Dependencies all met for dep_context=requeueable deps ti=<TaskInstance: citybikes_monitoring.get_and_insert_task scheduled__2025-08-17T00:07:00+00:00 [queued]>
[2025-08-17T21:38:26.568+0000] {taskinstance.py:2856} INFO - Starting attempt 1 of 1
[2025-08-17T21:38:26.670+0000] {taskinstance.py:2879} INFO - Executing <Task(PythonOperator): get_and_insert_task> on 2025-08-17 00:07:00+00:00
[2025-08-17T21:38:26.698+0000] {standard_task_runner.py:72} INFO - Started process 244 to run task
[2025-08-17T21:38:26.709+0000] {standard_task_runner.py:104} INFO - Running: ['airflow', 'tasks', 'run', 'citybikes_monitoring', 'get_and_insert_task', 'scheduled__2025-08-17T00:07:00+00:00', '--job-id', '9', '--raw', '--subdir', 'DAGS_FOLDER/example_01_python_operator.py', '--cfg-path', '/tmp/tmprqvh_glr']
[2025-08-17T21:38:26.722+0000] {standard_task_runner.py:105} INFO - Job 9: Subtask get_and_insert_task
[2025-08-17T21:38:26.789+0000] {logging_mixin.py:190} WARNING - /home/airflow/.local/lib/python3.10/site-packages/airflow/settings.py:209 DeprecationWarning: The sql_alchemy_conn option in [core] has been moved to the sql_alchemy_conn option in [database] - the old setting has been used, but please update your config.
[2025-08-17T21:38:26.891+0000] {task_command.py:467} INFO - Running <TaskInstance: citybikes_monitoring.get_and_insert_task scheduled__2025-08-17T00:07:00+00:00 [running]> on host e167319ee8f7
[2025-08-17T21:38:26.895+0000] {logging_mixin.py:190} WARNING - /home/airflow/.local/lib/python3.10/site-packages/airflow/settings.py:449 DeprecationWarning: The sql_alchemy_conn option in [core] has been moved to the sql_alchemy_conn option in [database] - the old setting has been used, but please update your config.
[2025-08-17T21:38:27.207+0000] {taskinstance.py:3122} INFO - Exporting env vars: AIRFLOW_CTX_DAG_OWNER='airflow' AIRFLOW_CTX_DAG_ID='citybikes_monitoring' AIRFLOW_CTX_TASK_ID='get_and_insert_task' AIRFLOW_CTX_EXECUTION_DATE='2025-08-17T00:07:00+00:00' AIRFLOW_CTX_TRY_NUMBER='1' AIRFLOW_CTX_DAG_RUN_ID='scheduled__2025-08-17T00:07:00+00:00'
[2025-08-17T21:38:27.212+0000] {taskinstance.py:731} INFO - ::endgroup::
[2025-08-17T21:38:28.373+0000] {taskinstance.py:3301} ERROR - Task failed with exception
Traceback (most recent call last):
  File "/home/airflow/.local/lib/python3.10/site-packages/airflow/models/taskinstance.py", line 767, in _execute_task
    result = _execute_callable(context=context, **execute_callable_kwargs)
  File "/home/airflow/.local/lib/python3.10/site-packages/airflow/models/taskinstance.py", line 733, in _execute_callable
    return ExecutionCallableRunner(
  File "/home/airflow/.local/lib/python3.10/site-packages/airflow/utils/operator_helpers.py", line 252, in run
    return self.func(*args, **kwargs)
  File "/home/airflow/.local/lib/python3.10/site-packages/airflow/models/baseoperator.py", line 406, in wrapper
    return func(self, *args, **kwargs)
  File "/home/airflow/.local/lib/python3.10/site-packages/airflow/operators/python.py", line 238, in execute
    return_value = self.execute_callable()
  File "/home/airflow/.local/lib/python3.10/site-packages/airflow/operators/python.py", line 256, in execute_callable
    return runner.run(*self.op_args, **self.op_kwargs)
  File "/home/airflow/.local/lib/python3.10/site-packages/airflow/utils/operator_helpers.py", line 252, in run
    return self.func(*args, **kwargs)
  File "/opt/airflow/dags/example_01_python_operator.py", line 45, in get_and_insert_data
    conn = psycopg2.connect(
  File "/home/airflow/.local/lib/python3.10/site-packages/psycopg2/__init__.py", line 122, in connect
    conn = _connect(dsn, connection_factory=connection_factory, **kwasync)
psycopg2.OperationalError: connection to server at "localhost" (::1), port 5432 failed: Connection refused
	Is the server running on that host and accepting TCP/IP connections?
connection to server at "localhost" (127.0.0.1), port 5432 failed: Connection refused
	Is the server running on that host and accepting TCP/IP connections?

[2025-08-17T21:38:28.395+0000] {taskinstance.py:1225} INFO - Marking task as FAILED. dag_id=citybikes_monitoring, task_id=get_and_insert_task, run_id=scheduled__2025-08-17T00:07:00+00:00, execution_date=20250817T000700, start_date=20250817T213826, end_date=20250817T213828
[2025-08-17T21:38:28.412+0000] {taskinstance.py:340} INFO - ::group::Post task execution logs
[2025-08-17T21:38:28.417+0000] {standard_task_runner.py:124} ERROR - Failed to execute job 9 for task get_and_insert_task (connection to server at "localhost" (::1), port 5432 failed: Connection refused
	Is the server running on that host and accepting TCP/IP connections?
connection to server at "localhost" (127.0.0.1), port 5432 failed: Connection refused
	Is the server running on that host and accepting TCP/IP connections?
; 244)
Traceback (most recent call last):
  File "/home/airflow/.local/lib/python3.10/site-packages/airflow/task/task_runner/standard_task_runner.py", line 117, in _start_by_fork
    ret = args.func(args, dag=self.dag)
  File "/home/airflow/.local/lib/python3.10/site-packages/airflow/cli/cli_config.py", line 49, in command
    return func(*args, **kwargs)
  File "/home/airflow/.local/lib/python3.10/site-packages/airflow/utils/cli.py", line 115, in wrapper
    return f(*args, **kwargs)
  File "/home/airflow/.local/lib/python3.10/site-packages/airflow/cli/commands/task_command.py", line 483, in task_run
    task_return_code = _run_task_by_selected_method(args, _dag, ti)
  File "/home/airflow/.local/lib/python3.10/site-packages/airflow/cli/commands/task_command.py", line 256, in _run_task_by_selected_method
    return _run_raw_task(args, ti)
  File "/home/airflow/.local/lib/python3.10/site-packages/airflow/cli/commands/task_command.py", line 341, in _run_raw_task
    return ti._run_raw_task(
  File "/home/airflow/.local/lib/python3.10/site-packages/airflow/utils/session.py", line 97, in wrapper
    return func(*args, session=session, **kwargs)
  File "/home/airflow/.local/lib/python3.10/site-packages/airflow/models/taskinstance.py", line 2995, in _run_raw_task
    return _run_raw_task(
  File "/home/airflow/.local/lib/python3.10/site-packages/airflow/models/taskinstance.py", line 273, in _run_raw_task
    TaskInstance._execute_task_with_callbacks(
  File "/home/airflow/.local/lib/python3.10/site-packages/airflow/models/taskinstance.py", line 3149, in _execute_task_with_callbacks
    result = self._execute_task(context, task_orig)
  File "/home/airflow/.local/lib/python3.10/site-packages/airflow/models/taskinstance.py", line 3173, in _execute_task
    return _execute_task(self, context, task_orig)
  File "/home/airflow/.local/lib/python3.10/site-packages/airflow/models/taskinstance.py", line 767, in _execute_task
    result = _execute_callable(context=context, **execute_callable_kwargs)
  File "/home/airflow/.local/lib/python3.10/site-packages/airflow/models/taskinstance.py", line 733, in _execute_callable
    return ExecutionCallableRunner(
  File "/home/airflow/.local/lib/python3.10/site-packages/airflow/utils/operator_helpers.py", line 252, in run
    return self.func(*args, **kwargs)
  File "/home/airflow/.local/lib/python3.10/site-packages/airflow/models/baseoperator.py", line 406, in wrapper
    return func(self, *args, **kwargs)
  File "/home/airflow/.local/lib/python3.10/site-packages/airflow/operators/python.py", line 238, in execute
    return_value = self.execute_callable()
  File "/home/airflow/.local/lib/python3.10/site-packages/airflow/operators/python.py", line 256, in execute_callable
    return runner.run(*self.op_args, **self.op_kwargs)
  File "/home/airflow/.local/lib/python3.10/site-packages/airflow/utils/operator_helpers.py", line 252, in run
    return self.func(*args, **kwargs)
  File "/opt/airflow/dags/example_01_python_operator.py", line 45, in get_and_insert_data
    conn = psycopg2.connect(
  File "/home/airflow/.local/lib/python3.10/site-packages/psycopg2/__init__.py", line 122, in connect
    conn = _connect(dsn, connection_factory=connection_factory, **kwasync)
psycopg2.OperationalError: connection to server at "localhost" (::1), port 5432 failed: Connection refused
	Is the server running on that host and accepting TCP/IP connections?
connection to server at "localhost" (127.0.0.1), port 5432 failed: Connection refused
	Is the server running on that host and accepting TCP/IP connections?

[2025-08-17T21:38:28.471+0000] {local_task_job_runner.py:261} INFO - Task exited with return code 1
[2025-08-17T21:38:28.495+0000] {local_task_job_runner.py:240} INFO - ::endgroup::
