[2025-08-17T21:51:30.237+0000] {local_task_job_runner.py:123} INFO - ::group::Pre task execution logs
[2025-08-17T21:51:30.252+0000] {taskinstance.py:2603} INFO - Dependencies all met for dep_context=non-requeueable deps ti=<TaskInstance: citybikes_monitoring.get_and_insert_task scheduled__2025-08-17T21:50:00+00:00 [queued]>
[2025-08-17T21:51:30.260+0000] {taskinstance.py:2603} INFO - Dependencies all met for dep_context=requeueable deps ti=<TaskInstance: citybikes_monitoring.get_and_insert_task scheduled__2025-08-17T21:50:00+00:00 [queued]>
[2025-08-17T21:51:30.263+0000] {taskinstance.py:2856} INFO - Starting attempt 1 of 1
[2025-08-17T21:51:30.275+0000] {taskinstance.py:2879} INFO - Executing <Task(PythonOperator): get_and_insert_task> on 2025-08-17 21:50:00+00:00
[2025-08-17T21:51:30.281+0000] {standard_task_runner.py:72} INFO - Started process 180 to run task
[2025-08-17T21:51:30.285+0000] {standard_task_runner.py:104} INFO - Running: ['airflow', 'tasks', 'run', 'citybikes_monitoring', 'get_and_insert_task', 'scheduled__2025-08-17T21:50:00+00:00', '--job-id', '2', '--raw', '--subdir', 'DAGS_FOLDER/example_01_python_operator.py', '--cfg-path', '/tmp/tmp705dyfn7']
[2025-08-17T21:51:30.289+0000] {standard_task_runner.py:105} INFO - Job 2: Subtask get_and_insert_task
[2025-08-17T21:51:30.306+0000] {logging_mixin.py:190} WARNING - /home/airflow/.local/lib/python3.10/site-packages/airflow/settings.py:209 DeprecationWarning: The sql_alchemy_conn option in [core] has been moved to the sql_alchemy_conn option in [database] - the old setting has been used, but please update your config.
[2025-08-17T21:51:30.364+0000] {task_command.py:467} INFO - Running <TaskInstance: citybikes_monitoring.get_and_insert_task scheduled__2025-08-17T21:50:00+00:00 [running]> on host bcb9240d170e
[2025-08-17T21:51:30.368+0000] {logging_mixin.py:190} WARNING - /home/airflow/.local/lib/python3.10/site-packages/airflow/settings.py:449 DeprecationWarning: The sql_alchemy_conn option in [core] has been moved to the sql_alchemy_conn option in [database] - the old setting has been used, but please update your config.
[2025-08-17T21:51:30.435+0000] {taskinstance.py:3122} INFO - Exporting env vars: AIRFLOW_CTX_DAG_OWNER='airflow' AIRFLOW_CTX_DAG_ID='citybikes_monitoring' AIRFLOW_CTX_TASK_ID='get_and_insert_task' AIRFLOW_CTX_EXECUTION_DATE='2025-08-17T21:50:00+00:00' AIRFLOW_CTX_TRY_NUMBER='1' AIRFLOW_CTX_DAG_RUN_ID='scheduled__2025-08-17T21:50:00+00:00'
[2025-08-17T21:51:30.438+0000] {taskinstance.py:731} INFO - ::endgroup::
[2025-08-17T21:51:31.564+0000] {taskinstance.py:3301} ERROR - Task failed with exception
Traceback (most recent call last):
  File "/home/airflow/.local/lib/python3.10/site-packages/airflow/models/taskinstance.py", line 767, in _execute_task
    result = _execute_callable(context=context, **execute_callable_kwargs)
  File "/home/airflow/.local/lib/python3.10/site-packages/airflow/models/taskinstance.py", line 733, in _execute_callable
    return ExecutionCallableRunner(
  File "/home/airflow/.local/lib/python3.10/site-packages/airflow/utils/operator_helpers.py", line 252, in run
    return self.func(*args, **kwargs)
  File "/home/airflow/.local/lib/python3.10/site-packages/airflow/models/baseoperator.py", line 406, in wrapper
    return func(self, *args, **kwargs)
  File "/home/airflow/.local/lib/python3.10/site-packages/airflow/operators/python.py", line 238, in execute
    return_value = self.execute_callable()
  File "/home/airflow/.local/lib/python3.10/site-packages/airflow/operators/python.py", line 256, in execute_callable
    return runner.run(*self.op_args, **self.op_kwargs)
  File "/home/airflow/.local/lib/python3.10/site-packages/airflow/utils/operator_helpers.py", line 252, in run
    return self.func(*args, **kwargs)
  File "/opt/airflow/dags/example_01_python_operator.py", line 62, in get_and_insert_data
    cur.execute(insert_query, tuple(row))
psycopg2.errors.UndefinedTable: relation "public.citybik_log" does not exist
LINE 2:         INSERT INTO public.citybik_log (id, updated_at, stat...
                            ^

[2025-08-17T21:51:31.584+0000] {taskinstance.py:1225} INFO - Marking task as FAILED. dag_id=citybikes_monitoring, task_id=get_and_insert_task, run_id=scheduled__2025-08-17T21:50:00+00:00, execution_date=20250817T215000, start_date=20250817T215130, end_date=20250817T215131
[2025-08-17T21:51:31.599+0000] {taskinstance.py:340} INFO - ::group::Post task execution logs
[2025-08-17T21:51:31.601+0000] {standard_task_runner.py:124} ERROR - Failed to execute job 2 for task get_and_insert_task (relation "public.citybik_log" does not exist
LINE 2:         INSERT INTO public.citybik_log (id, updated_at, stat...
                            ^
; 180)
Traceback (most recent call last):
  File "/home/airflow/.local/lib/python3.10/site-packages/airflow/task/task_runner/standard_task_runner.py", line 117, in _start_by_fork
    ret = args.func(args, dag=self.dag)
  File "/home/airflow/.local/lib/python3.10/site-packages/airflow/cli/cli_config.py", line 49, in command
    return func(*args, **kwargs)
  File "/home/airflow/.local/lib/python3.10/site-packages/airflow/utils/cli.py", line 115, in wrapper
    return f(*args, **kwargs)
  File "/home/airflow/.local/lib/python3.10/site-packages/airflow/cli/commands/task_command.py", line 483, in task_run
    task_return_code = _run_task_by_selected_method(args, _dag, ti)
  File "/home/airflow/.local/lib/python3.10/site-packages/airflow/cli/commands/task_command.py", line 256, in _run_task_by_selected_method
    return _run_raw_task(args, ti)
  File "/home/airflow/.local/lib/python3.10/site-packages/airflow/cli/commands/task_command.py", line 341, in _run_raw_task
    return ti._run_raw_task(
  File "/home/airflow/.local/lib/python3.10/site-packages/airflow/utils/session.py", line 97, in wrapper
    return func(*args, session=session, **kwargs)
  File "/home/airflow/.local/lib/python3.10/site-packages/airflow/models/taskinstance.py", line 2995, in _run_raw_task
    return _run_raw_task(
  File "/home/airflow/.local/lib/python3.10/site-packages/airflow/models/taskinstance.py", line 273, in _run_raw_task
    TaskInstance._execute_task_with_callbacks(
  File "/home/airflow/.local/lib/python3.10/site-packages/airflow/models/taskinstance.py", line 3149, in _execute_task_with_callbacks
    result = self._execute_task(context, task_orig)
  File "/home/airflow/.local/lib/python3.10/site-packages/airflow/models/taskinstance.py", line 3173, in _execute_task
    return _execute_task(self, context, task_orig)
  File "/home/airflow/.local/lib/python3.10/site-packages/airflow/models/taskinstance.py", line 767, in _execute_task
    result = _execute_callable(context=context, **execute_callable_kwargs)
  File "/home/airflow/.local/lib/python3.10/site-packages/airflow/models/taskinstance.py", line 733, in _execute_callable
    return ExecutionCallableRunner(
  File "/home/airflow/.local/lib/python3.10/site-packages/airflow/utils/operator_helpers.py", line 252, in run
    return self.func(*args, **kwargs)
  File "/home/airflow/.local/lib/python3.10/site-packages/airflow/models/baseoperator.py", line 406, in wrapper
    return func(self, *args, **kwargs)
  File "/home/airflow/.local/lib/python3.10/site-packages/airflow/operators/python.py", line 238, in execute
    return_value = self.execute_callable()
  File "/home/airflow/.local/lib/python3.10/site-packages/airflow/operators/python.py", line 256, in execute_callable
    return runner.run(*self.op_args, **self.op_kwargs)
  File "/home/airflow/.local/lib/python3.10/site-packages/airflow/utils/operator_helpers.py", line 252, in run
    return self.func(*args, **kwargs)
  File "/opt/airflow/dags/example_01_python_operator.py", line 62, in get_and_insert_data
    cur.execute(insert_query, tuple(row))
psycopg2.errors.UndefinedTable: relation "public.citybik_log" does not exist
LINE 2:         INSERT INTO public.citybik_log (id, updated_at, stat...
                            ^

[2025-08-17T21:51:31.629+0000] {local_task_job_runner.py:261} INFO - Task exited with return code 1
[2025-08-17T21:51:31.649+0000] {taskinstance.py:3891} INFO - 0 downstream tasks scheduled from follow-on schedule check
[2025-08-17T21:51:31.654+0000] {local_task_job_runner.py:240} INFO - ::endgroup::
